Workbook

Sheet ITICBCN Avaluació FINAL 25-26
B1: Nom | C1: Nota DUAL | D1: Nota presentació | E1: Nota documentació | F1: Total | G1: SAGA Projecte | I1: NIF empresa | J1: Data inici | K1: Data final | L1: Tutor | M1: Enllaç dossier | N1: Complecio
C2: 0.4 | D2: 0.3 | E2: 0.3 | F2: 1 | G2: ROUND
A3: ASIX | B3: Ismael Dumont Corcoles | E3: ='ITICBCN avaluació documentació '!R15 -> 0 | F3: =IF((AND($C3>=5,$D3>=5,$E3>=5)),C3*$C$2+D3*$D$2+E3*$E$2,0) -> 0 | G3: =ROUND(F3,0) -> 0 | I3: B75272823 | J3: 45756 | K3: 46115 | L3: Dani Garcia | N3: Abril
B4: Marcos Lopez Martinez | E4: ='ITICBCN avaluació documentació '!S15 -> 0 | F4: =IF((AND($C4>=5,$D4>=5,$E4>=5)),C4*$C$2+D4*$D$2+E4*$E$2,0) -> 0 | G4: =ROUND(F4,0) -> 0 | I4: B62619705 | J4: 45782 | K4: 46080 | L4: Xavi Lara | N4: Abril
B5: Denis Morales Ruiz | C5: 10 | D5: 3.93 | E5: 2.5 | F5: =IF((AND($C5>=5,$D5>=5,$E5>=5)),C5*$C$2+D5*$D$2+E5*$E$2,0) -> 0 | G5: =ROUND(F5,0) -> 0 | I5: B08282626 | J5: 45677 | K5: 45930 | L5: Xavi Lara | N5: Novembre
A7: DAM | B7: Keyla Estefani Baztin | E7: ='ITICBCN avaluació documentació '!V15 -> 0 | F7: =IF((AND($C7>=5,$D7>=5,$E7>=5)),C7*$C$2+D7*$D$2+E7*$E$2,0) -> 0 | G7: =ROUND(F7,0) -> 0 | I7: B55770747 | J7: 45845 | K7: 46101 | L7: Antonio Aguilar | N7: Abril
B8: Miguel Vera | C8: 10 | D8: 10 | E8: 10 | F8: =IF((AND($C8>=5,$D8>=5,$E8>=5)),C8*$C$2+D8*$D$2+E8*$E$2,0) -> 10 | G8: =ROUND(F8,0) -> 10 | I8: B60645405 | J8: 45769 | K8: 45991 | L8: David Fernandez | N8: Novembre
F9: 6.45 | G9: 6
E10: ='ITICBCN avaluació documentació '!Y15 -> 0 | F10: =IF((AND($C10>=5,$D10>=5,$E10>=5)),C10*$C$2+D10*$D$2+E10*$E$2,0) -> 0 | G10: =ROUND(F10,0) -> 0
E11: 5 | F11: =IF((AND($C11>=5,$D11>=5,$E11>=5)),C11*$C$2+D11*$D$2+E11*$E$2,0) -> 0 | G11: =ROUND(F11,0) -> 0
E12: ='ITICBCN avaluació documentació '!AA15 -> 0 | F12: =IF((AND($C12>=5,$D12>=5,$E12>=5)),C12*$C$2+D12*$D$2+E12*$E$2,0) -> 0 | G12: =ROUND(F12,0) -> 0
E13: ='ITICBCN avaluació documentació '!AB15 -> 0 | F13: =IF((AND($C13>=5,$D13>=5,$E13>=5)),C13*$C$2+D13*$D$2+E13*$E$2,0) -> 0 | G13: =ROUND(F13,0) -> 0
E14: ='ITICBCN avaluació documentació '!AC15 -> 0 | F14: =IF((AND($C14>=5,$D14>=5,$E14>=5)),C14*$C$2+D14*$D$2+E14*$E$2,0) -> 0 | G14: =ROUND(F14,0) -> 0
E15: ='ITICBCN avaluació documentació '!AD15 -> 0 | F15: =IF((AND($C15>=5,$D15>=5,$E15>=5)),C15*$C$2+D15*$D$2+E15*$E$2,0) -> 0 | G15: =ROUND(F15,0) -> 0
E16: ='ITICBCN avaluació documentació '!AE15 -> 0 | F16: =IF((AND($C16>=5,$D16>=5,$E16>=5)),C16*$C$2+D16*$D$2+E16*$E$2,0) -> 0 | G16: =ROUND(F16,0) -> 0
E17: ='ITICBCN avaluació documentació '!AF15 -> 0 | F17: =IF((AND($C17>=5,$D17>=5,$E17>=5)),C17*$C$2+D17*$D$2+E17*$E$2,0) -> 0 | G17: =ROUND(F17,0) -> 0
E18: ='ITICBCN avaluació documentació '!AG15 -> 0 | F18: =IF((AND($C18>=5,$D18>=5,$E18>=5)),C18*$C$2+D18*$D$2+E18*$E$2,0) -> 0 | G18: =ROUND(F18,0) -> 0
E19: ='ITICBCN avaluació documentació '!AH15 -> 0 | F19: =IF((AND($C19>=5,$D19>=5,$E19>=5)),C19*$C$2+D19*$D$2+E19*$E$2,0) -> 0 | G19: =ROUND(F19,0) -> 0
E20: ='ITICBCN avaluació documentació '!AI15 -> 0 | F20: =IF((AND($C20>=5,$D20>=5,$E20>=5)),C20*$C$2+D20*$D$2+E20*$E$2,0) -> 0 | G20: =ROUND(F20,0) -> 0
E21: ='ITICBCN avaluació documentació '!AJ15 -> 0 | F21: =IF((AND($C21>=5,$D21>=5,$E21>=5)),C21*$C$2+D21*$D$2+E21*$E$2,0) -> 0 | G21: =ROUND(F21,0) -> 0
D22: ='ITICBCN avaluació presentació 2'!AN14 | E22: ='ITICBCN avaluació documentació '!AK15 -> 0 | F22: =IF((AND($C22>=5,$D22>=5,$E22>=5)),C22*$C$2+D22*$D$2+E22*$E$2,0) -> 0 | G22: =ROUND(F22,0) -> 0
D23: ='ITICBCN avaluació presentació 2'!AN15 | E23: ='ITICBCN avaluació documentació '!AL15 -> 0 | F23: =IF((AND($C23>=5,$D23>=5,$E23>=5)),C23*$C$2+D23*$D$2+E23*$E$2,0) -> 0 | G23: =ROUND(F23,0) -> 0
D24: ='ITICBCN avaluació presentació 2'!AN16 | E24: ='ITICBCN avaluació documentació '!AM15 -> 0 | F24: =IF((AND($C24>=5,$D24>=5,$E24>=5)),C24*$C$2+D24*$D$2+E24*$E$2,0) -> 0 | G24: =ROUND(F24,0) -> 0
D25: ='ITICBCN avaluació presentació 2'!AN17 -> 0 | E25: ='ITICBCN avaluació documentació '!AN15 -> 0 | F25: =IF((AND($C25>=5,$D25>=5,$E25>=5)),C25*$C$2+D25*$D$2+E25*$E$2,0) -> 0 | G25: =ROUND(F25,0) -> 0
D26: ='ITICBCN avaluació presentació 2'!AO17 -> 0 | E26: ='ITICBCN avaluació documentació '!AO15 -> 0 | F26: =IF((AND($C26>=5,$D26>=5,$E26>=5)),C26*$C$2+D26*$D$2+E26*$E$2,0) -> 0 | G26: =ROUND(F26,0) -> 0
D27: ='ITICBCN avaluació presentació 2'!AP17 -> 0 | E27: ='ITICBCN avaluació documentació '!AP15 -> 0 | F27: =IF((AND($C27>=5,$D27>=5,$E27>=5)),C27*$C$2+D27*$D$2+E27*$E$2,0) -> 0 | G27: =ROUND(F27,0) -> 0
D28: ='ITICBCN avaluació presentació 2'!AQ17 -> 0 | E28: ='ITICBCN avaluació documentació '!AQ15 -> 0 | F28: =IF((AND($C28>=5,$D28>=5,$E28>=5)),C28*$C$2+D28*$D$2+E28*$E$2,0) -> 0 | G28: =ROUND(F28,0) -> 0
D29: ='ITICBCN avaluació presentació 2'!AR17 -> 0 | E29: ='ITICBCN avaluació documentació '!AR15 -> 0 | F29: =IF((AND($C29>=5,$D29>=5,$E29>=5)),C29*$C$2+D29*$D$2+E29*$E$2,0) -> 0 | G29: =ROUND(F29,0) -> 0
D30: ='ITICBCN avaluació presentació 2'!AS17 -> 0 | E30: ='ITICBCN avaluació documentació '!AS15 -> 0 | F30: =IF((AND($C30>=5,$D30>=5,$E30>=5)),C30*$C$2+D30*$D$2+E30*$E$2,0) -> 0 | G30: =ROUND(F30,0) -> 0
D31: ='ITICBCN avaluació presentació 2'!AT17 -> 0 | E31: ='ITICBCN avaluació documentació '!AT15 -> 0 | F31: =IF((AND($C31>=5,$D31>=5,$E31>=5)),C31*$C$2+D31*$D$2+E31*$E$2,0) -> 0 | G31: =ROUND(F31,0) -> 0
D32: ='ITICBCN avaluació presentació 2'!AU17 -> 0 | E32: ='ITICBCN avaluació documentació '!AU15 -> 0 | F32: =IF((AND($C32>=5,$D32>=5,$E32>=5)),C32*$C$2+D32*$D$2+E32*$E$2,0) -> 0 | G32: =ROUND(F32,0) -> 0
D33: ='ITICBCN avaluació presentació 2'!AV17 -> 0 | E33: ='ITICBCN avaluació documentació '!AV15 -> 0 | F33: =IF((AND($C33>=5,$D33>=5,$E33>=5)),C33*$C$2+D33*$D$2+E33*$E$2,0) -> 0 | G33: =ROUND(F33,0) -> 0
D34: ='ITICBCN avaluació presentació 2'!AW17 -> 0 | E34: ='ITICBCN avaluació documentació '!AW15 -> 0 | F34: =IF((AND($C34>=5,$D34>=5,$E34>=5)),C34*$C$2+D34*$D$2+E34*$E$2,0) -> 0 | G34: =ROUND(F34,0) -> 0
D35: ='ITICBCN avaluació presentació 2'!AX17 -> 0 | E35: ='ITICBCN avaluació documentació '!AX15 -> 0 | F35: =IF((AND($C35>=5,$D35>=5,$E35>=5)),C35*$C$2+D35*$D$2+E35*$E$2,0) -> 0 | G35: =ROUND(F35,0) -> 0
D36: ='ITICBCN avaluació presentació 2'!AY17 -> 0 | E36: ='ITICBCN avaluació documentació '!AY15 -> 0 | F36: =IF((AND($C36>=5,$D36>=5,$E36>=5)),C36*$C$2+D36*$D$2+E36*$E$2,0) -> 0 | G36: =ROUND(F36,0) -> 0
D37: ='ITICBCN avaluació presentació 2'!AZ17 -> 0 | E37: 10 | F37: =IF((AND($C37>=5,$D37>=5,$E37>=5)),C37*$C$2+D37*$D$2+E37*$E$2,0) -> 0 | G37: =ROUND(F37,0) -> 0
D38: ='ITICBCN avaluació presentació 2'!BA17 -> 0 | E38: ='ITICBCN avaluació documentació '!BA15 -> 0 | F38: =IF((AND($C38>=5,$D38>=5,$E38>=5)),C38*$C$2+D38*$D$2+E38*$E$2,0) -> 0 | G38: =ROUND(F38,0) -> 0

Sheet ITICBCN avaluació presentació 2
F2: Miguel Vera | G2: Denis Morales
A3: Llenguatge verbal | B3: Llenguatge poc correcte. Cap vocabulari específic. | C3: Mancances d’expressió. Poc vocabulari específic. | D3: Correcte. Adequat (en general). | E3: Molt bona locució. Ús de vocabulari específic. Expressa les idees amb claredat. | F3: 4 | G3: 2 | AI3: 4 | AJ3: 3 | AK3: 2 | AL3: 2
B4: 1punts | C4: 2punts | D4: 3punts | E4: 4punts
A5: Llenguatge no verbal | B5: Gesticulació absent o excessiva. Mirada fixa en un punt. Llegeixen notes contínuament. | C5: La gesticulació no adient. No capten l’interès del públic. Recorren sovint a la lectura de notes. | D5: Gesticulació adient. Llegeixen una part de l’exposició. | E5: La mirada s’estén per tota la classe. Els braços descriuen moviments harmònics amb la veu. La paraula s’adiu amb el gest. | F5: 4 | G5: 1 | AI5: 3 | AJ5: 3 | AK5: 3 | AL5: 2
B6: 1punts | C6: 2punts | D6: 3punts | E6: 4punts
A7: Material de suport | B7: Poc visual i poc treballat. La informació de suport és principalment llegida. El text conté nombroses faltes d'ortografia. | C7: Visualment agradable. No il·lustra els continguts més importants. Manca important d’imatges o massa lletra. El text conté faltes d'ortografia. | D7: Ben treballat visualment. No il·lustra alguns continguts importants. Falten imatges o massa lletra. | E7: Molt ben treballat visualment. Adequat als continguts. Carrega de lletra adequada. | F7: 4 | G7: 1 | AI7: 3 | AJ7: 2 | AK7: 2 | AL7: 2
B8: 1punts | C8: 2punts | D8: 3punts | E8: 4punts
A9: Explicació de l'estada a nivell tècnic (tasques, tecnologies...) | B9: No expliquen bé l'estada a les pràctiques. No han sabut respondre correctament les preguntes després de l’exposició. | C9: Han explicat l'estada de manera superficial. Només han contestat part de les qüestions. | D9: Han explicat bé l'estada però han faltat punts. Han contestat les preguntes o dubtes, però amb poc convenciment. | E9: Expliquen adecuadament la seva estada. Han contestat correctament les preguntes o dubtes. | F9: 4 | G9: 1 | AI9: 4 | AJ9: 2 | AK9: 2 | AL9: 3
B10: 1punts | C10: 2punts | D10: 3punts | E10: 4punts
A11: Context, motivació i objectius | B11: No expliquen les expectatives, objectius, motivació inial... | C11: Expliquen de manera breu, poc concisa, superficial i/o desordenada els objectius, la motivació... | D11: Expliquen correctament els objectius, la motivació, les expectatives però ho fan breument | E11: Exposen de manera clara la motivació i els objectius inicials. | F11: 4 | G11: 2 | AI11: 4 | AJ11: 2 | AK11: 3 | AL11: 2
B12: 1punts | C12: 2punts | D12: 3punts | E12: 4punts
A13: Conclusió | B13: No fan una conclusió del projecte. | C13: La conclusió que fan és molt breu i poc concisa. | D13: Descriuen de manera breu la trajectòria de les pràctiques, els punts forts i febles però no fa una valoració de les expectatives inicials | E13: Descriu la trajectòria de les pràctiques, els punts forts i febles i fa una valoració de les expectatives inicials | F13: 4 | G13: 2 | AI13: 4 | AJ13: 2 | AK13: 3 | AL13: 2
B14: 1punts | C14: 2punts | D14: 3punts | E14: 4punts
A15: General | B15: Gens clara. Gens ordenada. Costa de seguir. | C15: Poc clara. Poc ordenada. Es pot seguir. | D15: Correcta. | E15: Correcta. Ordenada. Fàcil de seguir. | F15: 4 | G15: 2 | AI15: 4 | AJ15: 3 | AK15: 3 | AL15: 3
B16: 1punts | C16: 2punts | D16: 3punts | E16: 4punts
A17: Total | E17: 28 | F17: =SUM(F3:F16)/($E$17)*10 -> 10 | G17: =SUM(G3:G16)/($E$17)*10 -> 3.9285714 | H17: =SUM(H3:H16)/($E$17)*10 -> 0 | I17: =SUM(I3:I16)/($E$17)*10 -> 0 | J17: =SUM(J3:J16)/($E$17)*10 -> 0 | K17: =SUM(K3:K16)/($E$17)*10 -> 0 | L17: =SUM(L3:L16)/($E$17)*10 -> 0 | M17: =SUM(M3:M16)/($E$17)*10 -> 0 | ... AB17: =SUM(AB3:AB16)/($E$17)*10 -> 0 | AI17: =SUM(AI3:AI16)/($E$17)*10 -> 9.2857143 | AJ17: =SUM(AJ3:AJ16)/($E$17)*10 -> 6.0714286 | AK17: =SUM(AK3:AK16)/($E$17)*10 -> 6.4285714 | AL17: =SUM(AL3:AL16)/($E$17)*10 -> 5.7142857 | AM17: =SUM(AM3:AM16)/($E$17)*10 -> 0 | AN17: =SUM(AN3:AN16)/($E$17)*10 -> 0 | AO17: =SUM(AO3:AO16)/($E$17)*10 -> 0 | AP17: =SUM(AP3:AP16)/($E$17)*10 -> 0 | ... BD17: =SUM(BD3:BD16)/($E$17)*10 -> 0 | BE17: =SUM(BE3:BE16)/($E$17-4)*10 -> 0 | BF17: =SUM(BF3:BF16)/($E$17-4)*10 -> 0 | BG17: =SUM(BG3:BG16)/($E$17-4)*10 -> 0 | BH17: =SUM(BH3:BH16)/$E$17*10 -> 0 | BI17: =SUM(BI3:BI16)/$E$17*10 -> 0 | BJ17: =SUM(BJ3:BJ16)/$E$17*10 -> 0 | BK17: =SUM(BK3:BK16)/$E$17*10 -> 0 | BL17: =SUM(BL3:BL16)/$E$17*10 -> 0 | BM17: =SUM(BM3:BM16)/$E$17*10 -> 0 | BN17: =SUM(BN3:BN16)/$E$17*10 -> 0 | BO17: =SUM(BO3:BO16)/$E$17*10 -> 0 | ... BX17: =SUM(BX3:BX16)/$E$17*10 -> 0

Sheet ITICBCN avaluació documentació 
F2: Miquel Vera | G2: Denis Morales
A3: Presentació Dossier | B3: Poc visual i poc treballat. | C3: Correcte. Adequat (en general). | D3: Visualment agradable | E3: Ben estructurat | F3: 4 | G3: 1
B4: 1punts | C4: 2punts | D4: 3punts | E4: 4punts
A5: Estructura Dossier | B5: Creats tots els apartats. | C5: Correcte. Adequat (en general). | D5: Fàcil la cerca d'informació en el document. | E5: Totes els apartats inclosos en el document. | F5: 4 | G5: 1
B6: 1punts | C6: 2punts | D6: 3punts | E6: 4punts
A7: Expressió escrita | B7: Llenguatge poc correcte. Cap vocabulari específic. | C7: Mancances d’expressió. Poc vocabulari específic. | D7: S'inclou vocabulari específic. | E7: Expresa amb professionalitat les tasques realitzades. | F7: 4 | G7: 1
B8: 1punts | C8: 2punts | D8: 3punts | E8: 4punts
A9: Activitats Inicials 1-5 | B9: No expliquen els objectius i motivació del projecte. | C9: Expliquen de manera breu, poc concisa, superficial i/o desordenada els objectius i la motivació. | D9: Expliquen correctament els objectius i la motivació, però es deixen algun dels punts o ho fan de manera poc detallada. | E9: Exposen de manera clara la motivació i els objectius del projecte. | F9: 4 | G9: 1
B10: 1punts | C10: 2punts | D10: 3punts | E10: 4punts
A11: Activitats 6 Aprenentatges adquirits | B11: No es detallen les tecnologies utilitzades. | C11: Expliquen de manera breu les tecnologies utilitzades i les tasques concretes realitzades. | D11: Expliquen correctament les tecnologies i les tasques concretesrealitzades però ho fan de manera poc detallada. | E11: Exposa de manera clara les tecnologies utilitzades i les tasques concretes realitzades. | F11: 4 | G11: 1
B12: 1punts | C12: 2punts | D12: 3punts | E12: 4punts
A13: Act7. Valoració de la estada a la empresa | F13: 4 | G13: 1
B14: 1punts | C14: 2punts | D14: 3punts | E14: 4punts
A15: Total | E15: =4*6 -> 24 | F15: =SUM(F3:F14)*10/24 -> 10 | G15: =SUM(G3:G14)*10/24 -> 2.5 | H15: =SUM(H3:H14)*10/24 -> 0 | I15: =SUM(I3:I14)*10/24 -> 0 | J15: =SUM(J3:J14)*10/24 -> 0 | K15: =SUM(K3:K14)*10/24 -> 0 | L15: =SUM(L3:L14)*10/24 -> 0 | M15: =SUM(M3:M14)*10/24 -> 0 | ... BS15: =SUM(BS3:BS14)*10/24 -> 0

Sheet Horaris 25-26
D1: Tribunal
A2: Data | B2: Classe | C2: Alumne | D2: Coordinació | E2: Coordinacio | F2: Tutor | G2: Estat | H2: Comentari
A3: 45971.604 | B3: DAM2B | C3: Vera Fernández, Miguel Alfonso | D3: Maria Olivella Romagosa | E3: Toni Talens Gimenez | F3: David Fernàndez Solé | G3: OK | H3: Confirmat
A4: 45973.604 | B4: ASIX2A | C4: Denis Morales Ruiz | D4: Maria Olivella Romagosa | E4: Toni Talens Gimenez | F4: Xavier Lara Moreno | G4: OK | H4: Confirmat
A5: 46147.583 | B5: ASIX2A | C5: Caballero Enero, Arnau | D5: Maria Olivella Romagosa | E5: Xavier Lara Moreno | F5: Xavier Lara Moreno
A6: 46147.597 | B6: ASIX2A | C6: Colet Ayllo, Daniel | D6: Maria Olivella Romagosa | E6: Xavier Lara Moreno | F6: Xavier Lara Moreno
A7: 46147.611 | B7: ASIX2A | C7: Fernández Marino, Javier | D7: Maria Olivella Romagosa | E7: Xavier Lara Moreno | F7: Xavier Lara Moreno
A8: 46147.625 | B8: ASIX2A | C8: García Martínez, Pablo | D8: Maria Olivella Romagosa | E8: Xavier Lara Moreno | F8: Xavier Lara Moreno
A9: 46147.639 | B9: ASIXCOM | C9: López Martínez, Marcos | D9: Maria Olivella Romagosa | E9: Xavier Lara Moreno | F9: Xavier Lara Moreno
A10: 46147.653 | B10: ASIX2A | C10: Marcos Lopez Martinez | D10: Maria Olivella Romagosa | E10: Toni Talens Gimenez | F10: Xavier Lara Moreno
A11: 46147.667 | B11: ASIX2A | C11: Mas Sales, Pau | D11: Maria Olivella Romagosa | E11: Xavier Lara Moreno | F11: Xavier Lara Moreno
A12: 46147.681 | B12: ASIXCOM | C12: Morales Ruiz, Denís | D12: Maria Olivella Romagosa | E12: Xavier Lara Moreno | F12: Xavier Lara Moreno
A13: 46147.694 | B13: ASIXCOM | C13: Murcia Arcas, Oriol | D13: Maria Olivella Romagosa | E13: Xavier Lara Moreno | F13: Xavier Lara Moreno
A14: 46147.708 | B14: ASIX2A | C14: Noval Juanola, Lluis | D14: Maria Olivella Romagosa | E14: Xavier Lara Moreno | F14: Xavier Lara Moreno
A15: 46147.722 | B15: ASIX2A | C15: Oñate Villagrasa, Aitana | D15: Maria Olivella Romagosa | E15: Xavier Lara Moreno | F15: Xavier Lara Moreno
A16: 46147.736 | B16: ASIX2A | C16: Ozuna Peña, Josther Alinton | D16: Maria Olivella Romagosa | E16: Xavier Lara Moreno | F16: Xavier Lara Moreno
... A50: 46155.639 | B50: DAW2A | C50: Sau López, Joan | D50: Maria Olivella Romagosa | E50: Xavier Lara Moreno | F50: Roger Sobrino Gil
B51: DAM2A | C51: Keyla Estefani Baztin | D51: Maria Olivella Romagosa | E51: Toni Talens Gimenez | F51: Toni Talens Gimenez | H51: Pendent

Sheet Calendari 25-26
B1: Roger Sobrino | C1: Juanma Sanchez | D1: Toni Aguilar | E1: David Fernandez | F1: Dani Garcia | G1: Xavi Lara | H1: Maria Olivella | I1: Roger Sobrino | J1: Juanma Sanchez | K1: Toni Aguilar | L1: David Fernandez | M1: Dani Garcia | N1: Xavi Lara | O1: Maria Olivella | P1: Roger Sobrino | Q1: Juanma Sanchez | R1: Toni Aguilar | S1: David Fernandez | T1: Dani Garcia | U1: Xavi Lara | V1: Maria Olivella | W1: Roger Sobrino | X1: Juanma Sanchez | Y1: Toni Aguilar | Z1: David Fernandez | AA1: Dani Garcia | AB1: Xavi Lara | AC1: Maria Olivella | AD1: Roger Sobrino | AE1: Juanma Sanchez | AF1: Toni Aguilar | AG1: David Fernandez | AH1: Dani Garcia | AI1: Xavi Lara | AJ1: Maria Olivella
B2: Lunes | I2: Martes | P2: Miercoles | W2: Jueves | AD2: Viernes
A3: 08:00-09:00 | B3: Out | C3: Out | D3: Out | E3: Out | F3: Out | G3: Out | H3: Out | I3: Out | J3: Out | K3: Out | L3: Out | M3: Out | N3: Out | O3: Out | P3: Out | Q3: Out | R3: Out | S3: Out | T3: Out | U3: Out | V3: Out | W3: Out | X3: Out | Y3: Out | Z3: Out | AA3: Out | AB3: Out | AC3: Out | AD3: Out | AE3: Out | AF3: Out | AG3: Out | AH3: Out | AI3: Out | AJ3: Out
A4: 09:00-10:00 | B4: Out | C4: Out | D4: Out | E4: Out | F4: Out | G4: Out | H4: Out | I4: Car | J4: Out | K4: Out | L4: Out | M4: Out | N4: Out | O4: Out | P4: Out | Q4: Out | R4: Out | S4: Out | T4: Out | U4: Out | V4: Out | W4: Out | X4: Out | Y4: Out | Z4: Out | AA4: Out | AB4: Out | AC4: Out | AD4: Out | AE4: Out | AF4: Class | AG4: Out | AH4: Out | AI4: Out | AJ4: Out
A5: 10:00-11:00 | B5: Out | C5: Out | D5: Out | E5: Out | F5: Out | G5: Out | H5: Out | I5: Car | J5: Out | K5: Out | L5: Out | M5: Out | N5: Out | O5: Out | P5: Out | Q5: Out | R5: Out | S5: Out | T5: Out | U5: Out | V5: Out | W5: Out | X5: Out | Y5: Out | Z5: Out | AA5: Out | AB5: Out | AC5: Out | AD5: Out | AE5: Out | AF5: Class | AG5: Out | AH5: Out | AI5: Out | AJ5: Out
A6: 11:00-11:30 | B6: Desc | C6: Desc | D6: Desc | E6: Desc | F6: Desc | G6: Desc | H6: Desc | I6: Desc | J6: Desc | K6: Desc | L6: Desc | M6: Desc | N6: Desc | O6: Desc | P6: Desc | Q6: Desc | R6: Desc | S6: Desc | T6: Desc | U6: Desc | V6: Desc | W6: Desc | X6: Desc | Y6: Desc | Z6: Desc | AA6: Desc | AB6: Desc | AC6: Desc | AD6: Desc | AE6: Desc | AF6: Desc | AG6: Desc | AH6: Desc | AI6: Desc | AJ6: Desc
A7: 11:30-12:30 | B7: Out | C7: Out | D7: Out | E7: Out | F7: Out | G7: Out | H7: Out | I7: Car | J7: Out | K7: Out | L7: Out | M7: Gua | N7: Out | O7: Out | P7: Out | Q7: Out | R7: Out | S7: Out | T7: Out | U7: Out | V7: Out | W7: Out | X7: Out | Y7: Out | Z7: Out | AA7: Out | AB7: Out | AC7: Out | AD7: Out | AE7: Out | AF7: Car | AG7: Out | AH7: Out | AI7: Out | AJ7: Out
A8: 12:30-13:30 | B8: Out | C8: Out | D8: Out | E8: Out | F8: Out | G8: Out | H8: Out | I8: Car | J8: Out | K8: Out | L8: Out | M8: Car | N8: Out | O8: Out | P8: Out | Q8: Out | R8: Out | S8: Out | T8: Out | U8: Out | V8: Out | W8: Out | X8: Out | Y8: Out | Z8: Out | AA8: Out | AB8: Out | AC8: Out | AD8: Out | AE8: Out | AF8: Car | AG8: Out | AH8: Out | AI8: Out | AJ8: Out
A9: 13:30-14:30 | B9: Out | C9: Out | D9: Out | E9: Out | F9: Out | G9: Out | H9: Car | I9: Coor | J9: Coor | K9: Coor | L9: Coor | M9: Coor | N9: Coor | O9: Coor | P9: Out | Q9: Out | R9: Out | S9: Out | T9: Out | U9: Out | V9: Car | W9: Out | X9: Out | Y9: Out | Z9: Out | AA9: Out | AB9: Out | AC9: Car | AD9: Out | AE9: Out | AF9: Car | AG9: Out | AH9: Out | AI9: Out | AJ9: Out
A10: 14:30-15:30 | B10: Out | C10: Car | D10: Out | E10: Out | F10: Car | G10: Out | H10: Car | I10: Coor | J10: Coor | K10: Coor | L10: Coor | M10: Coor | N10: Coor | O10: Coor | P10: Out | Q10: Out | R10: Car | S10: Out | T10: Car | U10: Car | V10: Car | W10: Out | X10: Out | Y10: Out | Z10: Out | AA10: Out | AB10: Car | AC10: Car | AD10: C.Tut | AE10: C.Tut | AF10: C.Tut | AG10: C.Tut | AH10: C.Tut | AI10: C.Tut | AJ10: Out
A11: 15:30-16:30 | B11: Class | C11: Car | D11: Out | E11: Class | F11: Proj | G11: Class | H11: Car | I11: Out | J11: Proj | K11: Proj | L11: Proj | M11: Proj | N11: Car | O11: Car | P11: Proj | Q11: Proj | R11: Proj | S11: Proj | T11: Proj | U11: Proj | V11: Car | W11: Proj | X11: Proj | Y11: Proj | Z11: Proj | AA11: Proj | AB11: Car | AC11: Car | AD11: Gua | AE11: Class | AF11: Out | AG11: Class | AH11: Proj | AI11: Class | AJ11: Class
A12: 16:30-17:30 | B12: Class | C12: Car | D12: Out | E12: Class | F12: Proj | G12: Class | H12: Car | I12: Out | J12: Proj | K12: Proj | L12: Proj | M12: Proj | N12: Car | O12: Car | P12: Proj | Q12: Proj | R12: Proj | S12: Proj | T12: Proj | U12: Proj | V12: Car | W12: Proj | X12: Proj | Y12: Proj | Z12: Proj | AA12: Proj | AB12: Gua | AC12: Car | AD12: Gua | AE12: Class | AF12: Out | AG12: Class | AH12: Proj | AI12: Class | AJ12: Class
A13: 17:30-18:00 | B13: Desc | C13: Desc | D13: Desc | E13: Desc | F13: Desc | G13: Desc | H13: Desc | I13: Desc | J13: Desc | K13: Desc | L13: Desc | M13: Desc | N13: Desc | O13: Desc | P13: Desc | Q13: Desc | R13: Desc | S13: Desc | T13: Desc | U13: Desc | V13: Desc | W13: Desc | X13: Desc | Y13: Desc | Z13: Desc | AA13: Desc | AB13: Desc | AC13: Desc | AD13: Desc | AE13: Desc | AF13: Desc | AG13: Desc | AH13: Desc | AI13: Desc | AJ13: Desc
A14: 18:00-19:00 | B14: Class | C14: Gua | D14: Class | E14: Class | F14: Class | G14: Gua | H14: Car | I14: Out | J14: Class | K14: Class | L14: Class | M14: Class | N14: Car | O14: Gua | P14: Class | Q14: Class | R14: Gua | S14: Out | T14: Out | U14: Car | V14: Gua | W14: Class | X14: Class | Y14: Class | Z14: Gua | AA14: Class | AB14: Class | AC14: Gua | AD14: Out | AE14: Out | AF14: Out | AG14: Class | AH14: Out | AI14: Class | AJ14: Class
... A16: 20:00-21:00 | B16: Gua | C16: Out | D16: Out | E16: Out | F16: Out | G16: Out | H16: Out | I16: Out | J16: Out | K16: Out | L16: Out | M16: Out | N16: Out | O16: Out | P16: Class | Q16: Gua | R16: Out | S16: Out | T16: Out | U16: Out | V16: Out | W16: Tut | X16: Tut | Y16: Tut | Z16: Tut | AA16: Tut | AB16: Tut | AC16: Out | AD16: Out | AE16: Out | AF16: Out | AG16: Out | AH16: Out | AI16: Out | AJ16: Out
B19: CALENDARI CURS 2025 - 2026
B21: SETEMBRE 2025 | J21: OCTUBRE 2025 | R21: NOVEMBRE 2025 | Z21: DESEMBRE 2025
B22: Dl. | C22: Dm. | D22: Dc. | E22: Dj. | F22: Dv. | G22: Ds. | H22: Dg. | J22: Dl. | K22: Dm. | L22: Dc. | M22: Dj. | N22: Dv. | O22: Ds. | P22: Dg. | R22: Dl. | S22: Dm. | T22: Dc. | U22: Dj. | V22: Dv. | W22: Ds. | X22: Dg. | Z22: Dl. | AA22: Dm. | AB22: Dc. | AC22: Dj. | AD22: Dv. | AE22: Ds. | AF22: Dg.
B23: 1 | C23: 2 | D23: 3 | E23: 4 | F23: 5 | G23: 6 | H23: 7 | L23: 1 | M23: 2 | N23: 3 | O23: 4 | P23: 5 | Q23: 3 | W23: 1 | X23: 2 | Y23: 7 | Z23: 1 | AA23: 2 | AB23: 3 | AC23: 4 | AD23: 5 | AE23: 6 | AF23: 7 | AG23: 12
B24: 8 | C24: 9 | D24: 10 | E24: 11 | F24: 12 | G24: 13 | H24: 14 | J24: 6 | K24: 7 | L24: 8 | M24: 9 | N24: 10 | O24: 11 | P24: 12 | Q24: 4 | R24: 3 | S24: 4 | T24: 5 | U24: 6 | V24: 7 | W24: 8 | X24: 9 | Y24: 8 | Z24: 8 | AA24: 9 | AB24: 10 | AC24: 11 | AD24: 12 | AE24: 13 | AF24: 14 | AG24: 13
B25: 15 | C25: 16 | D25: 17 | E25: 18 | F25: 19 | G25: 20 | H25: 21 | I25: 1 | J25: 13 | K25: 14 | L25: 15 | M25: 16 | N25: 17 | O25: 18 | P25: 19 | Q25: 5 | R25: 10 | S25: 11 | T25: 12 | U25: 13 | V25: 14 | W25: 15 | X25: 16 | Y25: 9 | Z25: 15 | AA25: 16 | AB25: 17 | AC25: 18 | AD25: 19 | AE25: 20 | AF25: 21 | AG25: 14
B26: 22 | C26: 23 | D26: 24 | E26: 25 | F26: 26 | G26: 27 | H26: 28 | I26: 2 | J26: 20 | K26: 21 | L26: 22 | M26: 23 | N26: 24 | O26: 25 | P26: 26 | Q26: 6 | R26: 17 | S26: 18 | T26: 19 | U26: 20 | V26: 21 | W26: 22 | X26: 23 | Y26: 10 | Z26: 22 | AA26: 23 | AB26: 24 | AC26: 25 | AD26: 26 | AE26: 27 | AF26: 28 | AG26: -
B27: 29 | C27: 30 | I27: 3 | J27: 27 | K27: 28 | L27: 29 | M27: 30 | N27: 31 | Q27: 7 | R27: 24 | S27: 25 | T27: 26 | U27: 27 | V27: 28 | W27: 29 | X27: 30 | Y27: 11 | Z27: 29 | AA27: 30 | AB27: 31 | AG27: -
B28: 3 | C28: 3 | D28: 1 | E28: 2 | F28: 3 | J28: 4 | K28: 4 | L28: 5 | M28: 5 | N28: 4 | R28: 4 | S28: 4 | T28: 4 | U28: 4 | V28: 3 | Z28: 2 | AA28: 3 | AB28: 3 | AC28: 3 | AD28: 3
A29: Acum | B29: =B28 -> 3 | C29: =C28 -> 3 | D29: =D28 -> 1 | E29: =E28 -> 2 | F29: =F28 -> 3 | J29: =B29+J28 -> 7 | K29: =C29+K28 -> 7 | L29: =D29+L28 -> 6 | M29: =E29+M28 -> 7 | N29: =F29+N28 -> 7 | R29: =J29+R28 -> 11 | S29: =K29+S28 -> 11 | T29: =L29+T28 -> 10 | U29: =M29+U28 -> 11 | V29: =N29+V28 -> 10 | Z29: =R29+Z28 -> 13 | AA29: =S29+AA28 -> 14 | AB29: =T29+AB28 -> 13 | AC29: =U29+AC28 -> 14 | AD29: =V29+AD28 -> 13
B31: GENER 2026 | J31: FEBRER 2026 | R31: MARÇ 2026 | Z31: Descans setmanal, festius, lliure disposició i vacances.
B32: Dl. | C32: Dm. | D32: Dc. | E32: Dj. | F32: Dv. | G32: Ds. | H32: Dg. | J32: Dl. | K32: Dm. | L32: Dc. | M32: Dj. | N32: Dv. | O32: Ds. | P32: Dg. | R32: Dl. | S32: Dm. | T32: Dc. | U32: Dj. | V32: Dv. | W32: Ds. | X32: Dg. | Z32: Inici i final del curs.
E33: 1 | F33: 2 | G33: 3 | H33: 4 | I33: - | P33: 1 | Q33: =I37 -> 18 | X33: 1 | Y33: =Q37 -> 22 | Z33: Finals de trimestre a efectes d'avaluacions parcials.
B34: 5 | C34: 6 | D34: 7 | E34: 8 | F34: 9 | G34: 10 | H34: 11 | I34: 15 | J34: 2 | K34: 3 | L34: 4 | M34: 5 | N34: 6 | O34: 7 | P34: 8 | Q34: =Q33+1 -> 19 | R34: 2 | S34: 3 | T34: 4 | U34: 5 | V34: 6 | W34: 7 | X34: 8 | Y34: =Y33+1 -> 23 | Z34: Juntes d'avaluació.
B35: 12 | C35: 13 | D35: 14 | E35: 15 | F35: 16 | G35: 17 | H35: 18 | I35: =I34+1 -> 16 | J35: 9 | K35: 10 | L35: 11 | M35: 12 | N35: 13 | O35: 14 | P35: 15 | Q35: =Q34+1 -> 20 | R35: 9 | S35: 10 | T35: 11 | U35: 12 | V35: 13 | W35: 14 | X35: 15 | Y35: =Y34+1 -> 24 | Z35: Segona convocatòria.
B36: 19 | C36: 20 | D36: 21 | E36: 22 | F36: 23 | G36: 24 | H36: 25 | I36: =I35+1 -> 17 | J36: 16 | K36: 17 | L36: 18 | M36: 19 | N36: 20 | O36: 21 | P36: 22 | Q36: =Q35+1 -> 21 | R36: 16 | S36: 17 | T36: 18 | U36: 19 | V36: 20 | W36: 21 | X36: 22 | Y36: =Y35+1 -> 25 | Z36: Jornades especials (ciberweek, JEDAI, graduació, portes obertes, entrega de notes...).
B37: 26 | C37: 27 | D37: 28 | E37: 29 | F37: 30 | G37: 31 | I37: =I36+1 -> 18 | J37: 23 | K37: 24 | L37: 25 | M37: 26 | N37: 27 | O37: 28 | Q37: =Q36+1 -> 22 | R37: 23 | S37: 24 | T37: 25 | U37: 26 | V37: 27 | W37: 28 | X37: 29 | Y37: =Y36+1 -> 26
R38: 30 | S38: 31 | Y38: - | Z38: Jornada amb horari setmanal modificat.
B39: 3 | C39: 3 | D39: 3 | E39: 4 | F39: 4 | J39: 4 | K39: 3 | L39: 4 | M39: 4 | N39: 4 | R39: 4 | S39: 4 | T39: 4 | U39: 4 | V39: 4 | Z39: Períodes sense alumnat (tràmits, organització...).
A40: Acum | B40: =Z29+B39 -> 16 | C40: =AA29+C39 -> 17 | D40: =AB29+D39 -> 16 | E40: =AC29+E39 -> 18 | F40: =AD29+F39 -> 17 | J40: =B40+J39 -> 20 | K40: =C40+K39 -> 20 | L40: =D40+L39 -> 20 | M40: =E40+M39 -> 22 | N40: =F40+N39 -> 21 | R40: =J40+R39 -> 24 | S40: =K40+S39 -> 24 | T40: =L40+T39 -> 24 | U40: =M40+U39 -> 26 | V40: =N40+V39 -> 25
B42: ABRIL 2026 | J42: MAIG 2026 | R42: JUNY 2026 | Z42: JULIOL 2026
B43: Dl. | C43: Dm. | D43: Dc. | E43: Dj. | F43: Dv. | G43: Ds. | H43: Dg. | J43: Dl. | K43: Dm. | L43: Dc. | M43: Dj. | N43: Dv. | O43: Ds. | P43: Dg. | R43: Dl. | S43: Dm. | T43: Dc. | U43: Dj. | V43: Dv. | W43: Ds. | X43: Dg. | Z43: Dl. | AA43: Dm. | AB43: Dc. | AC43: Dj. | AD43: Dv. | AE43: Ds. | AF43: Dg.
D44: 1 | E44: 2 | F44: 3 | G44: 4 | H44: 5 | I44: - | N44: 1 | O44: 2 | P44: 3 | Q44: =I48 -> 30 | R44: 1 | S44: 2 | T44: 3 | U44: 4 | V44: 5 | W44: 6 | X44: 7 | Y44: 34 | AB44: 1 | AC44: 2 | AD44: 3 | AE44: 4 | AF44: 5
B45: 6 | C45: 7 | D45: 8 | E45: 9 | F45: 10 | G45: 11 | H45: 12 | I45: 27 | J45: 4 | K45: 5 | L45: 6 | M45: 7 | N45: 8 | O45: 9 | P45: 10 | Q45: =Q44+1 -> 31 | R45: 8 | S45: 9 | T45: 10 | U45: 11 | V45: 12 | W45: 13 | X45: 14 | Y45: =Y44+1 -> 35 | Z45: 6 | AA45: 7 | AB45: 8 | AC45: 9 | AD45: 10 | AE45: 11 | AF45: 12
B46: 13 | C46: 14 | D46: 15 | E46: 16 | F46: 17 | G46: 18 | H46: 19 | I46: =I45+1 -> 28 | J46: 11 | K46: 12 | L46: 13 | M46: 14 | N46: 15 | O46: 16 | P46: 17 | Q46: =Q45+1 -> 32 | R46: 15 | S46: 16 | T46: 17 | U46: 18 | V46: 19 | W46: 20 | X46: 21 | Y46: =Y45+1 -> 36 | Z46: 13 | AA46: 14 | AB46: 15 | AC46: 16 | AD46: 17 | AE46: 18 | AF46: 19
...
